{"uuid":"4e0ad0b9-78fd-4e50-94a8-4a4319cf3532","historyId":"369f0c5acf801c60f9c6e3e6ca92e6c9","fullName":"tests.SolutionTest.testDivfException","labels":[{"name":"package","value":"tests.SolutionTest"},{"name":"testClass","value":"tests.SolutionTest"},{"name":"testMethod","value":"testDivfException"},{"name":"parentSuite","value":"Default Suite"},{"name":"suite","value":"TAF 2"},{"name":"subSuite","value":"tests.SolutionTest"},{"name":"host","value":"MacBook-Pro-Nikita.local"},{"name":"thread","value":"72827@MacBook-Pro-Nikita.local.main(1)"},{"name":"framework","value":"testng"},{"name":"language","value":"java"}],"links":[],"name":"testDivfException","status":"broken","statusDetails":{"known":false,"muted":false,"flaky":false,"message":"\nExpected exception of type class java.lang.NullPointerException but got java.lang.AssertionError: neverno expected [2] but found [1]","trace":"org.testng.TestException: \nExpected exception of type class java.lang.NullPointerException but got java.lang.AssertionError: neverno expected [2] but found [1]\n\tat org.testng.internal.invokers.ExpectedExceptionsHolder.wrongException(ExpectedExceptionsHolder.java:67)\n\tat org.testng.internal.invokers.TestInvoker.considerExceptions(TestInvoker.java:843)\n\tat org.testng.internal.invokers.TestInvoker.invokeMethod(TestInvoker.java:714)\n\tat org.testng.internal.invokers.TestInvoker.invokeTestMethod(TestInvoker.java:220)\n\tat org.testng.internal.invokers.MethodRunner.runInSequence(MethodRunner.java:50)\n\tat org.testng.internal.invokers.TestInvoker$MethodInvocationAgent.invoke(TestInvoker.java:945)\n\tat org.testng.internal.invokers.TestInvoker.invokeTestMethods(TestInvoker.java:193)\n\tat org.testng.internal.invokers.TestMethodWorker.invokeTestMethods(TestMethodWorker.java:146)\n\tat org.testng.internal.invokers.TestMethodWorker.run(TestMethodWorker.java:128)\n\tat java.util.ArrayList.forEach(ArrayList.java:1259)\n\tat org.testng.TestRunner.privateRun(TestRunner.java:808)\n\tat org.testng.TestRunner.run(TestRunner.java:603)\n\tat org.testng.SuiteRunner.runTest(SuiteRunner.java:429)\n\tat org.testng.SuiteRunner.runSequentially(SuiteRunner.java:423)\n\tat org.testng.SuiteRunner.privateRun(SuiteRunner.java:383)\n\tat org.testng.SuiteRunner.run(SuiteRunner.java:326)\n\tat org.testng.SuiteRunnerWorker.runSuite(SuiteRunnerWorker.java:52)\n\tat org.testng.SuiteRunnerWorker.run(SuiteRunnerWorker.java:95)\n\tat org.testng.TestNG.runSuitesSequentially(TestNG.java:1249)\n\tat org.testng.TestNG.runSuitesLocally(TestNG.java:1169)\n\tat org.testng.TestNG.runSuites(TestNG.java:1092)\n\tat org.testng.TestNG.run(TestNG.java:1060)\n\tat com.intellij.rt.testng.IDEARemoteTestNG.run(IDEARemoteTestNG.java:66)\n\tat com.intellij.rt.testng.RemoteTestNGStarter.main(RemoteTestNGStarter.java:109)\nCaused by: java.lang.AssertionError: neverno expected [2] but found [1]\n\tat org.testng.Assert.fail(Assert.java:110)\n\tat org.testng.Assert.failNotEquals(Assert.java:1413)\n\tat org.testng.Assert.assertEqualsImpl(Assert.java:149)\n\tat org.testng.Assert.assertEquals(Assert.java:131)\n\tat org.testng.Assert.assertEquals(Assert.java:1240)\n\tat tests.SolutionTest.testDivfException(SolutionTest.java:59)\n\tat sun.reflect.NativeMethodAccessorImpl.invoke0(Native Method)\n\tat sun.reflect.NativeMethodAccessorImpl.invoke(NativeMethodAccessorImpl.java:62)\n\tat sun.reflect.DelegatingMethodAccessorImpl.invoke(DelegatingMethodAccessorImpl.java:43)\n\tat java.lang.reflect.Method.invoke(Method.java:498)\n\tat org.testng.internal.invokers.MethodInvocationHelper.invokeMethod(MethodInvocationHelper.java:135)\n\tat org.testng.internal.invokers.TestInvoker.invokeMethod(TestInvoker.java:673)\n\t... 21 more\n"},"stage":"finished","steps":[],"attachments":[],"parameters":[],"start":1656260916011,"stop":1656260916031}